Workbook

Sheet Inputs
A1: MachineCare vs outside vendor: inputs
A2: Edit BLUE cells only. Yellow fill = assumption to confirm. "Your sheet" = value from the spreadsheet you sent (21 Oct 2026). Every other sheet is calculated.
A4: Input | B4: Value | C4: Unit | D4: Source / note
A5: General
A6: Users (licences needed) | B6: 62 | C6: people | D6: Your sheet.
A7: Internal labour rate (loaded) | B7: 40 | C7: $ per hour | D7: Your sheet. Used for every internal hour on both sides; confirm with finance.
A8: Outside vendor (quote)
A9: Licence price | B9: 50 | C9: $ per user per month | D9: Vendor quote (your sheet).
A10: One-time installation fee | B10: 10000 | C10: $ | D10: Vendor quote (your sheet).
A11: Yearly licence price increase | B11: 0 | C11: % per year | D11: ASSUMPTION: 0% = flat price for 5 years. Ask the vendor for their renewal terms.
A12: Vendor system administration (internal) | B12: 1 | C12: hours per week | D12: ADDED ASSUMPTION: someone still manages users, settings and vendor contact. Set 0 to match your sheet.
A13: Security review: in-house security team
A14: MachineCare initial security review | B14: 20 | C14: hours | D14: Your sheet: $800 = 20 h at $40/h, done by our own security team.
A15: Vendor system initial security review | B15: 20 | C15: hours | D15: ADDED ASSUMPTION: our team must also review a vendor system (our data leaves our network). Set 0 to match your sheet.
A16: Yearly security re-check, MachineCare (years 2–5) | B16: 8 | C16: hours per year | D16: ADDED ASSUMPTION: patch and access review. Set 0 to match your sheet.
A17: Yearly security re-check, vendor (years 2–5) | B17: 8 | C17: hours per year | D17: ADDED ASSUMPTION: vendor access and data review. Set 0 to match your sheet.
A18: Data and training (needed with either option)
A19: Physical stock count | B19: 40 | C19: hours | D19: Your sheet had 80 h for data validation in total; split here 40 + 20 + 20.
A20: Bins, prices and supplier details | B20: 20 | C20: hours | D20: Part of the 80 h.
A21: Lead times and maintenance intervals | B21: 20 | C21: hours | D21: Part of the 80 h.
A22: Training per user | B22: 1 | C22: hours per user | D22: Your sheet.
A23: MachineCare one-time setup (our engineering)
A24: Upgrade to a supported Python/Flutter and re-test | B24: 24 | C24: hours | D24: Your sheet had 160 h in total; split here 24 + 40 + 40 + 24 + 32.
A25: Production server, HTTPS and deployment | B25: 40 | C25: hours | D25: Part of the 160 h.
A26: Company sign-in (SSO) and account setup | B26: 40 | C26: hours | D26: Part of the 160 h.
A27: Monitoring and scheduled backups | B27: 24 | C27: hours | D27: Part of the 160 h.
A28: User acceptance testing with each role | B28: 32 | C28: hours | D28: Part of the 160 h.
A29: MachineCare yearly running
A30: Server / VM hosting | B30: 900 | C30: $ per year | D30: Your sheet had $1,200/yr for hosting and backup storage; split here 900 + 300.
A31: Off-host backup storage | B31: 300 | C31: $ per year | D31: Part of the $1,200.
A32: Patching and monitoring | B32: 1.5 | C32: hours per week | D32: Your sheet had 4 h/week of support in total; split here 1.5 + 1.5 + 1.
A33: User help and fixes | B33: 1.5 | C33: hours per week | D33: Part of the 4 h/week.
A34: Small changes and improvements | B34: 1 | C34: hours per week | D34: Part of the 4 h/week.

Sheet Budget detail
A1: Side-by-side budget by category (US$)
A2: Year 1 = first year including one-time costs. Year 2+ = each later year. Linked to the Comparison sheet.
A4: Category | B4: Outside vendor · Year 1 | C4: Outside vendor · Year 2+ | D4: Outside vendor · 5 years | E4: MachineCare · Year 1 | F4: MachineCare · Year 2+ | G4: MachineCare · 5 years | H4: 5-year difference
A5: Licences and fees | B5: =Comparison!C6+Comparison!C7 -> 47200 | C5: =Comparison!D6+Comparison!D7 -> 37200 | D5: =Comparison!H6+Comparison!H7 -> 196000 | E5: =0 -> 0 | F5: =0 -> 0 | G5: =0 -> 0 | H5: =D5-G5 -> 196000
A6: Setup and deployment | B6: =0 -> 0 | C6: =0 -> 0 | D6: =0 -> 0 | E6: =Comparison!C22+Comparison!C23+Comparison!C24+Comparison!C25+Comparison!C26 -> 6400 | F6: =Comparison!D22+Comparison!D23+Comparison!D24+Comparison!D25+Comparison!D26 -> 0 | G6: =Comparison!H22+Comparison!H23+Comparison!H24+Comparison!H25+Comparison!H26 -> 6400 | H6: =D6-G6 -> -6400
A7: Security (in-house team) | B7: =Comparison!C9+Comparison!C10 -> 800 | C7: =Comparison!D9+Comparison!D10 -> 320 | D7: =Comparison!H9+Comparison!H10 -> 2080 | E7: =Comparison!C27+Comparison!C28 -> 800 | F7: =Comparison!D27+Comparison!D28 -> 320 | G7: =Comparison!H27+Comparison!H28 -> 2080 | H7: =D7-G7 -> 0
A8: Data preparation | B8: =Comparison!C11+Comparison!C12+Comparison!C13 -> 3200 | C8: =Comparison!D11+Comparison!D12+Comparison!D13 -> 0 | D8: =Comparison!H11+Comparison!H12+Comparison!H13 -> 3200 | E8: =Comparison!C29+Comparison!C30+Comparison!C31 -> 3200 | F8: =Comparison!D29+Comparison!D30+Comparison!D31 -> 0 | G8: =Comparison!H29+Comparison!H30+Comparison!H31 -> 3200 | H8: =D8-G8 -> 0
A9: Training | B9: =Comparison!C14 -> 2480 | C9: =Comparison!D14 -> 0 | D9: =Comparison!H14 -> 2480 | E9: =Comparison!C32 -> 2480 | F9: =Comparison!D32 -> 0 | G9: =Comparison!H32 -> 2480 | H9: =D9-G9 -> 0
A10: Hosting and backups | B10: =0 -> 0 | C10: =0 -> 0 | D10: =0 -> 0 | E10: =Comparison!C33+Comparison!C34 -> 1200 | F10: =Comparison!D33+Comparison!D34 -> 1200 | G10: =Comparison!H33+Comparison!H34 -> 6000 | H10: =D10-G10 -> -6000
A11: Running, support and administration | B11: =Comparison!C16 -> 2080 | C11: =Comparison!D16 -> 2080 | D11: =Comparison!H16 -> 10400 | E11: =Comparison!C35+Comparison!C36+Comparison!C37 -> 8320 | F11: =Comparison!D35+Comparison!D36+Comparison!D37 -> 8320 | G11: =Comparison!H35+Comparison!H36+Comparison!H37 -> 41600 | H11: =D11-G11 -> -31200
A12: Total | B12: =SUM(B5:B11) -> 55760 | C12: =SUM(C5:C11) -> 39600 | D12: =SUM(D5:D11) -> 214160 | E12: =SUM(E5:E11) -> 22400 | F12: =SUM(F5:F11) -> 9840 | G12: =SUM(G5:G11) -> 61760 | H12: =SUM(H5:H11) -> 152400
A14: Checks: totals must equal the Comparison sheet.
A15: Vendor 5-year check | D15: =D12-Comparison!H17 -> 0
A16: MachineCare 5-year check | G16: =G12-Comparison!H38 -> 0

Sheet Comparison
A1: 5-year comparison: every cost line, both options (US$)
A2: Calculated from Inputs. Year 1 includes all one-time costs.
A4: Cost line | B4: Basis | C4: Year 1 | D4: Year 2 | E4: Year 3 | F4: Year 4 | G4: Year 5 | H4: 5-year total
A5: OUTSIDE VENDOR
A6: Licences | B6: users × price × 12 (+ yearly increase) | C6: =Inputs!$B$9*Inputs!$B$6*12*(1+Inputs!$B$11)^0 -> 37200 | D6: =Inputs!$B$9*Inputs!$B$6*12*(1+Inputs!$B$11)^1 -> 37200 | E6: =Inputs!$B$9*Inputs!$B$6*12*(1+Inputs!$B$11)^2 -> 37200 | F6: =Inputs!$B$9*Inputs!$B$6*12*(1+Inputs!$B$11)^3 -> 37200 | G6: =Inputs!$B$9*Inputs!$B$6*12*(1+Inputs!$B$11)^4 -> 37200 | H6: =SUM(C6:G6) -> 186000
A7: Installation fee | B7: One-time, vendor quote | C7: =Inputs!$B$10 -> 10000 | D7: =0 -> 0 | E7: =0 -> 0 | F7: =0 -> 0 | G7: =0 -> 0 | H7: =SUM(C7:G7) -> 10000
A8: Setup and deployment | B8: Included in installation fee | C8: =0 -> 0 | D8: =0 -> 0 | E8: =0 -> 0 | F8: =0 -> 0 | G8: =0 -> 0 | H8: =SUM(C8:G8) -> 0
A9: Security review (in-house team) | B9: hours × rate | C9: =Inputs!$B$15*Inputs!$B$7 -> 800 | D9: =0 -> 0 | E9: =0 -> 0 | F9: =0 -> 0 | G9: =0 -> 0 | H9: =SUM(C9:G9) -> 800
A10: Yearly security re-check | B10: hours/yr × rate (yrs 2–5) | C10: =0 -> 0 | D10: =Inputs!$B$17*Inputs!$B$7 -> 320 | E10: =Inputs!$B$17*Inputs!$B$7 -> 320 | F10: =Inputs!$B$17*Inputs!$B$7 -> 320 | G10: =Inputs!$B$17*Inputs!$B$7 -> 320 | H10: =SUM(C10:G10) -> 1280
A11: Physical stock count | B11: hours × rate | C11: =Inputs!$B$19*Inputs!$B$7 -> 1600 | D11: =0 -> 0 | E11: =0 -> 0 | F11: =0 -> 0 | G11: =0 -> 0 | H11: =SUM(C11:G11) -> 1600
A12: Bins, prices and supplier details | B12: hours × rate | C12: =Inputs!$B$20*Inputs!$B$7 -> 800 | D12: =0 -> 0 | E12: =0 -> 0 | F12: =0 -> 0 | G12: =0 -> 0 | H12: =SUM(C12:G12) -> 800
A13: Lead times and maintenance intervals | B13: hours × rate | C13: =Inputs!$B$21*Inputs!$B$7 -> 800 | D13: =0 -> 0 | E13: =0 -> 0 | F13: =0 -> 0 | G13: =0 -> 0 | H13: =SUM(C13:G13) -> 800
A14: Training | B14: users × hours × rate | C14: =Inputs!$B$22*Inputs!$B$6*Inputs!$B$7 -> 2480 | D14: =0 -> 0 | E14: =0 -> 0 | F14: =0 -> 0 | G14: =0 -> 0 | H14: =SUM(C14:G14) -> 2480
A15: Hosting and backups | B15: Included in subscription | C15: =0 -> 0 | D15: =0 -> 0 | E15: =0 -> 0 | F15: =0 -> 0 | G15: =0 -> 0 | H15: =SUM(C15:G15) -> 0
A16: System administration (internal) | B16: hours/week × 52 × rate | C16: =Inputs!$B$12*52*Inputs!$B$7 -> 2080 | D16: =Inputs!$B$12*52*Inputs!$B$7 -> 2080 | E16: =Inputs!$B$12*52*Inputs!$B$7 -> 2080 | F16: =Inputs!$B$12*52*Inputs!$B$7 -> 2080 | G16: =Inputs!$B$12*52*Inputs!$B$7 -> 2080 | H16: =SUM(C16:G16) -> 10400
A17: Outside vendor total per year | C17: =SUM(C6:C16) -> 55760 | D17: =SUM(D6:D16) -> 39600 | E17: =SUM(E6:E16) -> 39600 | F17: =SUM(F6:F16) -> 39600 | G17: =SUM(G6:G16) -> 39600 | H17: =SUM(H6:H16) -> 214160
A19: MACHINECARE (IN-HOUSE)
A20: Licences | B20: None: built in-house | C20: =0 -> 0 | D20: =0 -> 0 | E20: =0 -> 0 | F20: =0 -> 0 | G20: =0 -> 0 | H20: =SUM(C20:G20) -> 0
A21: Installation fee | B21: None | C21: =0 -> 0 | D21: =0 -> 0 | E21: =0 -> 0 | F21: =0 -> 0 | G21: =0 -> 0 | H21: =SUM(C21:G21) -> 0
A22: Runtime upgrade and re-test | B22: hours × rate | C22: =Inputs!$B$24*Inputs!$B$7 -> 960 | D22: =0 -> 0 | E22: =0 -> 0 | F22: =0 -> 0 | G22: =0 -> 0 | H22: =SUM(C22:G22) -> 960
A23: Production server, HTTPS and deployment | B23: hours × rate | C23: =Inputs!$B$25*Inputs!$B$7 -> 1600 | D23: =0 -> 0 | E23: =0 -> 0 | F23: =0 -> 0 | G23: =0 -> 0 | H23: =SUM(C23:G23) -> 1600
A24: Company sign-in (SSO) | B24: hours × rate | C24: =Inputs!$B$26*Inputs!$B$7 -> 1600 | D24: =0 -> 0 | E24: =0 -> 0 | F24: =0 -> 0 | G24: =0 -> 0 | H24: =SUM(C24:G24) -> 1600
A25: Monitoring and scheduled backups | B25: hours × rate | C25: =Inputs!$B$27*Inputs!$B$7 -> 960 | D25: =0 -> 0 | E25: =0 -> 0 | F25: =0 -> 0 | G25: =0 -> 0 | H25: =SUM(C25:G25) -> 960
A26: User acceptance testing | B26: hours × rate | C26: =Inputs!$B$28*Inputs!$B$7 -> 1280 | D26: =0 -> 0 | E26: =0 -> 0 | F26: =0 -> 0 | G26: =0 -> 0 | H26: =SUM(C26:G26) -> 1280
A27: Security review (in-house team) | B27: hours × rate | C27: =Inputs!$B$14*Inputs!$B$7 -> 800 | D27: =0 -> 0 | E27: =0 -> 0 | F27: =0 -> 0 | G27: =0 -> 0 | H27: =SUM(C27:G27) -> 800
A28: Yearly security re-check | B28: hours/yr × rate (yrs 2–5) | C28: =0 -> 0 | D28: =Inputs!$B$16*Inputs!$B$7 -> 320 | E28: =Inputs!$B$16*Inputs!$B$7 -> 320 | F28: =Inputs!$B$16*Inputs!$B$7 -> 320 | G28: =Inputs!$B$16*Inputs!$B$7 -> 320 | H28: =SUM(C28:G28) -> 1280
A29: Physical stock count | B29: hours × rate | C29: =Inputs!$B$19*Inputs!$B$7 -> 1600 | D29: =0 -> 0 | E29: =0 -> 0 | F29: =0 -> 0 | G29: =0 -> 0 | H29: =SUM(C29:G29) -> 1600
A30: Bins, prices and supplier details | B30: hours × rate | C30: =Inputs!$B$20*Inputs!$B$7 -> 800 | D30: =0 -> 0 | E30: =0 -> 0 | F30: =0 -> 0 | G30: =0 -> 0 | H30: =SUM(C30:G30) -> 800
A31: Lead times and maintenance intervals | B31: hours × rate | C31: =Inputs!$B$21*Inputs!$B$7 -> 800 | D31: =0 -> 0 | E31: =0 -> 0 | F31: =0 -> 0 | G31: =0 -> 0 | H31: =SUM(C31:G31) -> 800
A32: Training | B32: users × hours × rate | C32: =Inputs!$B$22*Inputs!$B$6*Inputs!$B$7 -> 2480 | D32: =0 -> 0 | E32: =0 -> 0 | F32: =0 -> 0 | G32: =0 -> 0 | H32: =SUM(C32:G32) -> 2480
A33: Server / VM hosting | B33: $ per year | C33: =Inputs!$B$30 -> 900 | D33: =Inputs!$B$30 -> 900 | E33: =Inputs!$B$30 -> 900 | F33: =Inputs!$B$30 -> 900 | G33: =Inputs!$B$30 -> 900 | H33: =SUM(C33:G33) -> 4500
A34: Off-host backup storage | B34: $ per year | C34: =Inputs!$B$31 -> 300 | D34: =Inputs!$B$31 -> 300 | E34: =Inputs!$B$31 -> 300 | F34: =Inputs!$B$31 -> 300 | G34: =Inputs!$B$31 -> 300 | H34: =SUM(C34:G34) -> 1500
A35: Patching and monitoring | B35: hours/week × 52 × rate | C35: =Inputs!$B$32*52*Inputs!$B$7 -> 3120 | D35: =Inputs!$B$32*52*Inputs!$B$7 -> 3120 | E35: =Inputs!$B$32*52*Inputs!$B$7 -> 3120 | F35: =Inputs!$B$32*52*Inputs!$B$7 -> 3120 | G35: =Inputs!$B$32*52*Inputs!$B$7 -> 3120 | H35: =SUM(C35:G35) -> 15600
A36: User help and fixes | B36: hours/week × 52 × rate | C36: =Inputs!$B$33*52*Inputs!$B$7 -> 3120 | D36: =Inputs!$B$33*52*Inputs!$B$7 -> 3120 | E36: =Inputs!$B$33*52*Inputs!$B$7 -> 3120 | F36: =Inputs!$B$33*52*Inputs!$B$7 -> 3120 | G36: =Inputs!$B$33*52*Inputs!$B$7 -> 3120 | H36: =SUM(C36:G36) -> 15600
A37: Small changes and improvements | B37: hours/week × 52 × rate | C37: =Inputs!$B$34*52*Inputs!$B$7 -> 2080 | D37: =Inputs!$B$34*52*Inputs!$B$7 -> 2080 | E37: =Inputs!$B$34*52*Inputs!$B$7 -> 2080 | F37: =Inputs!$B$34*52*Inputs!$B$7 -> 2080 | G37: =Inputs!$B$34*52*Inputs!$B$7 -> 2080 | H37: =SUM(C37:G37) -> 10400
A38: MachineCare total per year | C38: =SUM(C20:C37) -> 22400 | D38: =SUM(D20:D37) -> 9840 | E38: =SUM(E20:E37) -> 9840 | F38: =SUM(F20:F37) -> 9840 | G38: =SUM(G20:G37) -> 9840 | H38: =SUM(H20:H37) -> 61760
A40: Cumulative: outside vendor | C40: =SUM($C$17:C17) -> 55760 | D40: =SUM($C$17:D17) -> 95360 | E40: =SUM($C$17:E17) -> 134960 | F40: =SUM($C$17:F17) -> 174560 | G40: =SUM($C$17:G17) -> 214160
A41: Cumulative: MachineCare | C41: =SUM($C$38:C38) -> 22400 | D41: =SUM($C$38:D38) -> 32240 | E41: =SUM($C$38:E38) -> 42080 | F41: =SUM($C$38:F38) -> 51920 | G41: =SUM($C$38:G38) -> 61760
A42: Cumulative saving with MachineCare | C42: =C40-C41 -> 33360 | D42: =D40-D41 -> 63120 | E42: =E40-E41 -> 92880 | F42: =F40-F41 -> 122640 | G42: =G40-G41 -> 152400
A44: Running cost per user per month (Year 2, after one-time costs)
...
